[2024-02-28T05:59:32.310+0000] {taskinstance.py:1956} INFO - Dependencies all met for dep_context=non-requeueable deps ti=<TaskInstance: gcs_snowflake_etl.transform_data scheduled__2024-02-27T00:00:00+00:00 [queued]>
[2024-02-28T05:59:32.333+0000] {taskinstance.py:1956} INFO - Dependencies all met for dep_context=requeueable deps ti=<TaskInstance: gcs_snowflake_etl.transform_data scheduled__2024-02-27T00:00:00+00:00 [queued]>
[2024-02-28T05:59:32.334+0000] {taskinstance.py:2170} INFO - Starting attempt 3 of 3
[2024-02-28T05:59:32.364+0000] {taskinstance.py:2191} INFO - Executing <Task(PythonOperator): transform_data> on 2024-02-27 00:00:00+00:00
[2024-02-28T05:59:32.374+0000] {standard_task_runner.py:60} INFO - Started process 65 to run task
[2024-02-28T05:59:32.383+0000] {standard_task_runner.py:87} INFO - Running: ['***', 'tasks', 'run', 'gcs_snowflake_etl', 'transform_data', 'scheduled__2024-02-27T00:00:00+00:00', '--job-id', '51', '--raw', '--subdir', 'DAGS_FOLDER/GCS_to_Snowflake_DAG.py', '--cfg-path', '/tmp/tmp0yfx_b5q']
[2024-02-28T05:59:32.390+0000] {standard_task_runner.py:88} INFO - Job 51: Subtask transform_data
[2024-02-28T05:59:32.488+0000] {task_command.py:423} INFO - Running <TaskInstance: gcs_snowflake_etl.transform_data scheduled__2024-02-27T00:00:00+00:00 [running]> on host ae154badcbc6
[2024-02-28T05:59:32.648+0000] {taskinstance.py:2480} INFO - Exporting env vars: AIRFLOW_CTX_DAG_OWNER='stellar' AIRFLOW_CTX_DAG_ID='gcs_snowflake_etl' AIRFLOW_CTX_TASK_ID='transform_data' AIRFLOW_CTX_EXECUTION_DATE='2024-02-27T00:00:00+00:00' AIRFLOW_CTX_TRY_NUMBER='3' AIRFLOW_CTX_DAG_RUN_ID='scheduled__2024-02-27T00:00:00+00:00'
[2024-02-28T05:59:32.770+0000] {_default.py:338} WARNING - Authentication failed using Compute Engine authentication due to unavailable metadata server.
[2024-02-28T05:59:32.790+0000] {_metadata.py:208} WARNING - Compute Engine Metadata server unavailable on attempt 1 of 5. Reason: HTTPConnectionPool(host='metadata.google.internal', port=80): Max retries exceeded with url: /computeMetadata/v1/instance/service-accounts/default/?recursive=true (Caused by NewConnectionError('<urllib3.connection.HTTPConnection object at 0x7f3d63d30100>: Failed to establish a new connection: [Errno -2] Name or service not known'))
[2024-02-28T05:59:32.813+0000] {_metadata.py:208} WARNING - Compute Engine Metadata server unavailable on attempt 2 of 5. Reason: HTTPConnectionPool(host='metadata.google.internal', port=80): Max retries exceeded with url: /computeMetadata/v1/instance/service-accounts/default/?recursive=true (Caused by NewConnectionError('<urllib3.connection.HTTPConnection object at 0x7f3d63d30550>: Failed to establish a new connection: [Errno -2] Name or service not known'))
[2024-02-28T05:59:32.832+0000] {_metadata.py:208} WARNING - Compute Engine Metadata server unavailable on attempt 3 of 5. Reason: HTTPConnectionPool(host='metadata.google.internal', port=80): Max retries exceeded with url: /computeMetadata/v1/instance/service-accounts/default/?recursive=true (Caused by NewConnectionError('<urllib3.connection.HTTPConnection object at 0x7f3d63d309d0>: Failed to establish a new connection: [Errno -2] Name or service not known'))
[2024-02-28T05:59:32.851+0000] {_metadata.py:208} WARNING - Compute Engine Metadata server unavailable on attempt 4 of 5. Reason: HTTPConnectionPool(host='metadata.google.internal', port=80): Max retries exceeded with url: /computeMetadata/v1/instance/service-accounts/default/?recursive=true (Caused by NewConnectionError('<urllib3.connection.HTTPConnection object at 0x7f3d63d30f70>: Failed to establish a new connection: [Errno -2] Name or service not known'))
[2024-02-28T05:59:32.869+0000] {_metadata.py:208} WARNING - Compute Engine Metadata server unavailable on attempt 5 of 5. Reason: HTTPConnectionPool(host='metadata.google.internal', port=80): Max retries exceeded with url: /computeMetadata/v1/instance/service-accounts/default/?recursive=true (Caused by NewConnectionError('<urllib3.connection.HTTPConnection object at 0x7f3d63d30820>: Failed to establish a new connection: [Errno -2] Name or service not known'))
[2024-02-28T05:59:33.710+0000] {retry.py:157} ERROR - _request non-retriable exception: Anonymous caller does not have storage.objects.get access to the Google Cloud Storage object. Permission 'storage.objects.get' denied on resource (or it may not exist)., 401
Traceback (most recent call last):
  File "/home/airflow/.local/lib/python3.8/site-packages/gcsfs/retry.py", line 123, in retry_request
    return await func(*args, **kwargs)
  File "/home/airflow/.local/lib/python3.8/site-packages/gcsfs/core.py", line 430, in _request
    validate_response(status, contents, path, args)
  File "/home/airflow/.local/lib/python3.8/site-packages/gcsfs/retry.py", line 110, in validate_response
    raise HttpError(error)
gcsfs.retry.HttpError: Anonymous caller does not have storage.objects.get access to the Google Cloud Storage object. Permission 'storage.objects.get' denied on resource (or it may not exist)., 401
[2024-02-28T05:59:33.712+0000] {taskinstance.py:2698} ERROR - Task failed with exception
Traceback (most recent call last):
  File "/home/airflow/.local/lib/python3.8/site-packages/airflow/models/taskinstance.py", line 433, in _execute_task
    result = execute_callable(context=context, **execute_callable_kwargs)
  File "/home/airflow/.local/lib/python3.8/site-packages/airflow/operators/python.py", line 199, in execute
    return_value = self.execute_callable()
  File "/home/airflow/.local/lib/python3.8/site-packages/airflow/operators/python.py", line 216, in execute_callable
    return self.python_callable(*self.op_args, **self.op_kwargs)
  File "/opt/airflow/dags/GCS_to_Snowflake_DAG.py", line 25, in transform_data
    df = pd.read_csv("gs://us_stock_market/US-Stock-Market-Dataset.csv")
  File "/home/airflow/.local/lib/python3.8/site-packages/pandas/io/parsers/readers.py", line 912, in read_csv
    return _read(filepath_or_buffer, kwds)
  File "/home/airflow/.local/lib/python3.8/site-packages/pandas/io/parsers/readers.py", line 577, in _read
    parser = TextFileReader(filepath_or_buffer, **kwds)
  File "/home/airflow/.local/lib/python3.8/site-packages/pandas/io/parsers/readers.py", line 1407, in __init__
    self._engine = self._make_engine(f, self.engine)
  File "/home/airflow/.local/lib/python3.8/site-packages/pandas/io/parsers/readers.py", line 1661, in _make_engine
    self.handles = get_handle(
  File "/home/airflow/.local/lib/python3.8/site-packages/pandas/io/common.py", line 716, in get_handle
    ioargs = _get_filepath_or_buffer(
  File "/home/airflow/.local/lib/python3.8/site-packages/pandas/io/common.py", line 414, in _get_filepath_or_buffer
    file_obj = fsspec.open(
  File "/home/airflow/.local/lib/python3.8/site-packages/fsspec/core.py", line 135, in open
    return self.__enter__()
  File "/home/airflow/.local/lib/python3.8/site-packages/fsspec/core.py", line 103, in __enter__
    f = self.fs.open(self.path, mode=mode)
  File "/home/airflow/.local/lib/python3.8/site-packages/fsspec/spec.py", line 1295, in open
    f = self._open(
  File "/home/airflow/.local/lib/python3.8/site-packages/gcsfs/core.py", line 1516, in _open
    return GCSFile(
  File "/home/airflow/.local/lib/python3.8/site-packages/gcsfs/core.py", line 1675, in __init__
    super().__init__(
  File "/home/airflow/.local/lib/python3.8/site-packages/fsspec/spec.py", line 1651, in __init__
    self.size = self.details["size"]
  File "/home/airflow/.local/lib/python3.8/site-packages/gcsfs/core.py", line 1711, in details
    self._details = self.fs.info(self.path, generation=self.generation)
  File "/home/airflow/.local/lib/python3.8/site-packages/fsspec/asyn.py", line 118, in wrapper
    return sync(self.loop, func, *args, **kwargs)
  File "/home/airflow/.local/lib/python3.8/site-packages/fsspec/asyn.py", line 103, in sync
    raise return_result
  File "/home/airflow/.local/lib/python3.8/site-packages/fsspec/asyn.py", line 56, in _runner
    result[0] = await coro
  File "/home/airflow/.local/lib/python3.8/site-packages/gcsfs/core.py", line 959, in _info
    exact = await self._get_object(path)
  File "/home/airflow/.local/lib/python3.8/site-packages/gcsfs/core.py", line 516, in _get_object
    res = await self._call(
  File "/home/airflow/.local/lib/python3.8/site-packages/gcsfs/core.py", line 437, in _call
    status, headers, info, contents = await self._request(
  File "/home/airflow/.local/lib/python3.8/site-packages/decorator.py", line 221, in fun
    return await caller(func, *(extras + args), **kw)
  File "/home/airflow/.local/lib/python3.8/site-packages/gcsfs/retry.py", line 158, in retry_request
    raise e
  File "/home/airflow/.local/lib/python3.8/site-packages/gcsfs/retry.py", line 123, in retry_request
    return await func(*args, **kwargs)
  File "/home/airflow/.local/lib/python3.8/site-packages/gcsfs/core.py", line 430, in _request
    validate_response(status, contents, path, args)
  File "/home/airflow/.local/lib/python3.8/site-packages/gcsfs/retry.py", line 110, in validate_response
    raise HttpError(error)
gcsfs.retry.HttpError: Anonymous caller does not have storage.objects.get access to the Google Cloud Storage object. Permission 'storage.objects.get' denied on resource (or it may not exist)., 401
[2024-02-28T05:59:33.746+0000] {taskinstance.py:1138} INFO - Marking task as FAILED. dag_id=gcs_snowflake_etl, task_id=transform_data, execution_date=20240227T000000, start_date=20240228T055932, end_date=20240228T055933
[2024-02-28T05:59:33.770+0000] {standard_task_runner.py:107} ERROR - Failed to execute job 51 for task transform_data (Anonymous caller does not have storage.objects.get access to the Google Cloud Storage object. Permission 'storage.objects.get' denied on resource (or it may not exist)., 401; 65)
[2024-02-28T05:59:33.802+0000] {local_task_job_runner.py:234} INFO - Task exited with return code 1
[2024-02-28T05:59:33.843+0000] {taskinstance.py:3280} INFO - 0 downstream tasks scheduled from follow-on schedule check
[2024-02-28T12:13:37.561+0000] {taskinstance.py:1956} INFO - Dependencies all met for dep_context=non-requeueable deps ti=<TaskInstance: gcs_snowflake_etl.transform_data scheduled__2024-02-27T00:00:00+00:00 [queued]>
[2024-02-28T12:13:37.575+0000] {taskinstance.py:1956} INFO - Dependencies all met for dep_context=requeueable deps ti=<TaskInstance: gcs_snowflake_etl.transform_data scheduled__2024-02-27T00:00:00+00:00 [queued]>
[2024-02-28T12:13:37.576+0000] {taskinstance.py:2170} INFO - Starting attempt 3 of 5
[2024-02-28T12:13:37.595+0000] {taskinstance.py:2191} INFO - Executing <Task(PythonOperator): transform_data> on 2024-02-27 00:00:00+00:00
[2024-02-28T12:13:37.602+0000] {standard_task_runner.py:60} INFO - Started process 76 to run task
[2024-02-28T12:13:37.606+0000] {standard_task_runner.py:87} INFO - Running: ['***', 'tasks', 'run', 'gcs_snowflake_etl', 'transform_data', 'scheduled__2024-02-27T00:00:00+00:00', '--job-id', '13', '--raw', '--subdir', 'DAGS_FOLDER/GCS_to_Snowflake_DAG.py', '--cfg-path', '/tmp/tmpb778vvjn']
[2024-02-28T12:13:37.611+0000] {standard_task_runner.py:88} INFO - Job 13: Subtask transform_data
[2024-02-28T12:13:37.695+0000] {task_command.py:423} INFO - Running <TaskInstance: gcs_snowflake_etl.transform_data scheduled__2024-02-27T00:00:00+00:00 [running]> on host b9a0bf70b495
[2024-02-28T12:13:37.845+0000] {taskinstance.py:2480} INFO - Exporting env vars: AIRFLOW_CTX_DAG_OWNER='stellar' AIRFLOW_CTX_DAG_ID='gcs_snowflake_etl' AIRFLOW_CTX_TASK_ID='transform_data' AIRFLOW_CTX_EXECUTION_DATE='2024-02-27T00:00:00+00:00' AIRFLOW_CTX_TRY_NUMBER='3' AIRFLOW_CTX_DAG_RUN_ID='scheduled__2024-02-27T00:00:00+00:00'
[2024-02-28T12:13:37.851+0000] {taskinstance.py:2698} ERROR - Task failed with exception
Traceback (most recent call last):
  File "/home/airflow/.local/lib/python3.8/site-packages/airflow/models/taskinstance.py", line 433, in _execute_task
    result = execute_callable(context=context, **execute_callable_kwargs)
  File "/home/airflow/.local/lib/python3.8/site-packages/airflow/operators/python.py", line 199, in execute
    return_value = self.execute_callable()
  File "/home/airflow/.local/lib/python3.8/site-packages/airflow/operators/python.py", line 216, in execute_callable
    return self.python_callable(*self.op_args, **self.op_kwargs)
  File "/opt/airflow/dags/GCS_to_Snowflake_DAG.py", line 36, in transform_data
    storage_client = storage.Client()
  File "/home/airflow/.local/lib/python3.8/site-packages/google/cloud/storage/client.py", line 172, in __init__
    super(Client, self).__init__(
  File "/home/airflow/.local/lib/python3.8/site-packages/google/cloud/client/__init__.py", line 320, in __init__
    _ClientProjectMixin.__init__(self, project=project, credentials=credentials)
  File "/home/airflow/.local/lib/python3.8/site-packages/google/cloud/client/__init__.py", line 268, in __init__
    project = self._determine_default(project)
  File "/home/airflow/.local/lib/python3.8/site-packages/google/cloud/client/__init__.py", line 287, in _determine_default
    return _determine_default_project(project)
  File "/home/airflow/.local/lib/python3.8/site-packages/google/cloud/_helpers/__init__.py", line 152, in _determine_default_project
    _, project = google.auth.default()
  File "/home/airflow/.local/lib/python3.8/site-packages/google/auth/_default.py", line 657, in default
    credentials, project_id = checker()
  File "/home/airflow/.local/lib/python3.8/site-packages/google/auth/_default.py", line 650, in <lambda>
    lambda: _get_explicit_environ_credentials(quota_project_id=quota_project_id),
  File "/home/airflow/.local/lib/python3.8/site-packages/google/auth/_default.py", line 270, in _get_explicit_environ_credentials
    credentials, project_id = load_credentials_from_file(
  File "/home/airflow/.local/lib/python3.8/site-packages/google/auth/_default.py", line 114, in load_credentials_from_file
    raise exceptions.DefaultCredentialsError(
google.auth.exceptions.DefaultCredentialsError: File D:\GCS_to_Snowflake_WithAirflow\credentials2de-workshop-369208-8179100cc99a.json was not found.
[2024-02-28T12:13:37.869+0000] {taskinstance.py:1138} INFO - Marking task as UP_FOR_RETRY. dag_id=gcs_snowflake_etl, task_id=transform_data, execution_date=20240227T000000, start_date=20240228T121337, end_date=20240228T121337
[2024-02-28T12:13:37.891+0000] {standard_task_runner.py:107} ERROR - Failed to execute job 13 for task transform_data (File D:\GCS_to_Snowflake_WithAirflow\credentials2de-workshop-369208-8179100cc99a.json was not found.; 76)
[2024-02-28T12:13:37.940+0000] {local_task_job_runner.py:234} INFO - Task exited with return code 1
[2024-02-28T12:13:38.003+0000] {taskinstance.py:3280} INFO - 0 downstream tasks scheduled from follow-on schedule check
[2024-02-28T12:22:39.100+0000] {taskinstance.py:1956} INFO - Dependencies all met for dep_context=non-requeueable deps ti=<TaskInstance: gcs_snowflake_etl.transform_data scheduled__2024-02-27T00:00:00+00:00 [queued]>
[2024-02-28T12:22:39.118+0000] {taskinstance.py:1956} INFO - Dependencies all met for dep_context=requeueable deps ti=<TaskInstance: gcs_snowflake_etl.transform_data scheduled__2024-02-27T00:00:00+00:00 [queued]>
[2024-02-28T12:22:39.119+0000] {taskinstance.py:2170} INFO - Starting attempt 3 of 5
[2024-02-28T12:22:39.139+0000] {taskinstance.py:2191} INFO - Executing <Task(PythonOperator): transform_data> on 2024-02-27 00:00:00+00:00
[2024-02-28T12:22:39.146+0000] {standard_task_runner.py:60} INFO - Started process 67 to run task
[2024-02-28T12:22:39.151+0000] {standard_task_runner.py:87} INFO - Running: ['***', 'tasks', 'run', 'gcs_snowflake_etl', 'transform_data', 'scheduled__2024-02-27T00:00:00+00:00', '--job-id', '24', '--raw', '--subdir', 'DAGS_FOLDER/GCS_to_Snowflake_DAG.py', '--cfg-path', '/tmp/tmp8se5ws1q']
[2024-02-28T12:22:39.157+0000] {standard_task_runner.py:88} INFO - Job 24: Subtask transform_data
[2024-02-28T12:22:39.238+0000] {task_command.py:423} INFO - Running <TaskInstance: gcs_snowflake_etl.transform_data scheduled__2024-02-27T00:00:00+00:00 [running]> on host b9a0bf70b495
[2024-02-28T12:22:39.346+0000] {taskinstance.py:2480} INFO - Exporting env vars: AIRFLOW_CTX_DAG_OWNER='stellar' AIRFLOW_CTX_DAG_ID='gcs_snowflake_etl' AIRFLOW_CTX_TASK_ID='transform_data' AIRFLOW_CTX_EXECUTION_DATE='2024-02-27T00:00:00+00:00' AIRFLOW_CTX_TRY_NUMBER='3' AIRFLOW_CTX_DAG_RUN_ID='scheduled__2024-02-27T00:00:00+00:00'
[2024-02-28T12:22:39.349+0000] {taskinstance.py:2698} ERROR - Task failed with exception
Traceback (most recent call last):
  File "/home/airflow/.local/lib/python3.8/site-packages/airflow/models/taskinstance.py", line 433, in _execute_task
    result = execute_callable(context=context, **execute_callable_kwargs)
  File "/home/airflow/.local/lib/python3.8/site-packages/airflow/operators/python.py", line 199, in execute
    return_value = self.execute_callable()
  File "/home/airflow/.local/lib/python3.8/site-packages/airflow/operators/python.py", line 216, in execute_callable
    return self.python_callable(*self.op_args, **self.op_kwargs)
  File "/opt/airflow/dags/GCS_to_Snowflake_DAG.py", line 36, in transform_data
    storage_client = storage.Client()
  File "/home/airflow/.local/lib/python3.8/site-packages/google/cloud/storage/client.py", line 172, in __init__
    super(Client, self).__init__(
  File "/home/airflow/.local/lib/python3.8/site-packages/google/cloud/client/__init__.py", line 320, in __init__
    _ClientProjectMixin.__init__(self, project=project, credentials=credentials)
  File "/home/airflow/.local/lib/python3.8/site-packages/google/cloud/client/__init__.py", line 268, in __init__
    project = self._determine_default(project)
  File "/home/airflow/.local/lib/python3.8/site-packages/google/cloud/client/__init__.py", line 287, in _determine_default
    return _determine_default_project(project)
  File "/home/airflow/.local/lib/python3.8/site-packages/google/cloud/_helpers/__init__.py", line 152, in _determine_default_project
    _, project = google.auth.default()
  File "/home/airflow/.local/lib/python3.8/site-packages/google/auth/_default.py", line 657, in default
    credentials, project_id = checker()
  File "/home/airflow/.local/lib/python3.8/site-packages/google/auth/_default.py", line 650, in <lambda>
    lambda: _get_explicit_environ_credentials(quota_project_id=quota_project_id),
  File "/home/airflow/.local/lib/python3.8/site-packages/google/auth/_default.py", line 270, in _get_explicit_environ_credentials
    credentials, project_id = load_credentials_from_file(
  File "/home/airflow/.local/lib/python3.8/site-packages/google/auth/_default.py", line 114, in load_credentials_from_file
    raise exceptions.DefaultCredentialsError(
google.auth.exceptions.DefaultCredentialsError: File ./credentials/r2de-workshop-369208-8179100cc99a.json was not found.
[2024-02-28T12:22:39.368+0000] {taskinstance.py:1138} INFO - Marking task as UP_FOR_RETRY. dag_id=gcs_snowflake_etl, task_id=transform_data, execution_date=20240227T000000, start_date=20240228T122239, end_date=20240228T122239
[2024-02-28T12:22:39.387+0000] {standard_task_runner.py:107} ERROR - Failed to execute job 24 for task transform_data (File ./credentials/r2de-workshop-369208-8179100cc99a.json was not found.; 67)
[2024-02-28T12:22:39.405+0000] {local_task_job_runner.py:234} INFO - Task exited with return code 1
[2024-02-28T12:22:39.441+0000] {taskinstance.py:3280} INFO - 0 downstream tasks scheduled from follow-on schedule check
[2024-02-28T12:49:54.266+0000] {taskinstance.py:1956} INFO - Dependencies all met for dep_context=non-requeueable deps ti=<TaskInstance: gcs_snowflake_etl.transform_data scheduled__2024-02-27T00:00:00+00:00 [queued]>
[2024-02-28T12:49:54.282+0000] {taskinstance.py:1956} INFO - Dependencies all met for dep_context=requeueable deps ti=<TaskInstance: gcs_snowflake_etl.transform_data scheduled__2024-02-27T00:00:00+00:00 [queued]>
[2024-02-28T12:49:54.283+0000] {taskinstance.py:2170} INFO - Starting attempt 3 of 5
[2024-02-28T12:49:54.301+0000] {taskinstance.py:2191} INFO - Executing <Task(PythonOperator): transform_data> on 2024-02-27 00:00:00+00:00
[2024-02-28T12:49:54.306+0000] {standard_task_runner.py:60} INFO - Started process 85 to run task
[2024-02-28T12:49:54.313+0000] {standard_task_runner.py:87} INFO - Running: ['***', 'tasks', 'run', 'gcs_snowflake_etl', 'transform_data', 'scheduled__2024-02-27T00:00:00+00:00', '--job-id', '50', '--raw', '--subdir', 'DAGS_FOLDER/GCS_to_Snowflake_DAG.py', '--cfg-path', '/tmp/tmpicehk7u8']
[2024-02-28T12:49:54.318+0000] {standard_task_runner.py:88} INFO - Job 50: Subtask transform_data
[2024-02-28T12:49:54.391+0000] {task_command.py:423} INFO - Running <TaskInstance: gcs_snowflake_etl.transform_data scheduled__2024-02-27T00:00:00+00:00 [running]> on host b9a0bf70b495
[2024-02-28T12:49:54.497+0000] {taskinstance.py:2480} INFO - Exporting env vars: AIRFLOW_CTX_DAG_OWNER='stellar' AIRFLOW_CTX_DAG_ID='gcs_snowflake_etl' AIRFLOW_CTX_TASK_ID='transform_data' AIRFLOW_CTX_EXECUTION_DATE='2024-02-27T00:00:00+00:00' AIRFLOW_CTX_TRY_NUMBER='3' AIRFLOW_CTX_DAG_RUN_ID='scheduled__2024-02-27T00:00:00+00:00'
[2024-02-28T12:49:54.500+0000] {taskinstance.py:2698} ERROR - Task failed with exception
Traceback (most recent call last):
  File "/home/airflow/.local/lib/python3.8/site-packages/airflow/models/taskinstance.py", line 433, in _execute_task
    result = execute_callable(context=context, **execute_callable_kwargs)
  File "/home/airflow/.local/lib/python3.8/site-packages/airflow/operators/python.py", line 199, in execute
    return_value = self.execute_callable()
  File "/home/airflow/.local/lib/python3.8/site-packages/airflow/operators/python.py", line 216, in execute_callable
    return self.python_callable(*self.op_args, **self.op_kwargs)
  File "/opt/airflow/dags/GCS_to_Snowflake_DAG.py", line 36, in transform_data
    storage_client = storage.Client()
  File "/home/airflow/.local/lib/python3.8/site-packages/google/cloud/storage/client.py", line 172, in __init__
    super(Client, self).__init__(
  File "/home/airflow/.local/lib/python3.8/site-packages/google/cloud/client/__init__.py", line 320, in __init__
    _ClientProjectMixin.__init__(self, project=project, credentials=credentials)
  File "/home/airflow/.local/lib/python3.8/site-packages/google/cloud/client/__init__.py", line 268, in __init__
    project = self._determine_default(project)
  File "/home/airflow/.local/lib/python3.8/site-packages/google/cloud/client/__init__.py", line 287, in _determine_default
    return _determine_default_project(project)
  File "/home/airflow/.local/lib/python3.8/site-packages/google/cloud/_helpers/__init__.py", line 152, in _determine_default_project
    _, project = google.auth.default()
  File "/home/airflow/.local/lib/python3.8/site-packages/google/auth/_default.py", line 657, in default
    credentials, project_id = checker()
  File "/home/airflow/.local/lib/python3.8/site-packages/google/auth/_default.py", line 650, in <lambda>
    lambda: _get_explicit_environ_credentials(quota_project_id=quota_project_id),
  File "/home/airflow/.local/lib/python3.8/site-packages/google/auth/_default.py", line 270, in _get_explicit_environ_credentials
    credentials, project_id = load_credentials_from_file(
  File "/home/airflow/.local/lib/python3.8/site-packages/google/auth/_default.py", line 114, in load_credentials_from_file
    raise exceptions.DefaultCredentialsError(
google.auth.exceptions.DefaultCredentialsError: File D:\GCS_to_Snowflake_WithAirflow2de-workshop-369208-8179100cc99a.json was not found.
[2024-02-28T12:49:54.520+0000] {taskinstance.py:1138} INFO - Marking task as UP_FOR_RETRY. dag_id=gcs_snowflake_etl, task_id=transform_data, execution_date=20240227T000000, start_date=20240228T124954, end_date=20240228T124954
[2024-02-28T12:49:54.536+0000] {standard_task_runner.py:107} ERROR - Failed to execute job 50 for task transform_data (File D:\GCS_to_Snowflake_WithAirflow2de-workshop-369208-8179100cc99a.json was not found.; 85)
[2024-02-28T12:49:54.565+0000] {local_task_job_runner.py:234} INFO - Task exited with return code 1
[2024-02-28T12:49:54.622+0000] {taskinstance.py:3280} INFO - 0 downstream tasks scheduled from follow-on schedule check
[2024-02-28T13:07:35.099+0000] {taskinstance.py:1956} INFO - Dependencies all met for dep_context=non-requeueable deps ti=<TaskInstance: gcs_snowflake_etl.transform_data scheduled__2024-02-27T00:00:00+00:00 [queued]>
[2024-02-28T13:07:35.115+0000] {taskinstance.py:1956} INFO - Dependencies all met for dep_context=requeueable deps ti=<TaskInstance: gcs_snowflake_etl.transform_data scheduled__2024-02-27T00:00:00+00:00 [queued]>
[2024-02-28T13:07:35.117+0000] {taskinstance.py:2170} INFO - Starting attempt 3 of 5
[2024-02-28T13:07:35.159+0000] {taskinstance.py:2191} INFO - Executing <Task(PythonOperator): transform_data> on 2024-02-27 00:00:00+00:00
[2024-02-28T13:07:35.165+0000] {standard_task_runner.py:60} INFO - Started process 75 to run task
[2024-02-28T13:07:35.171+0000] {standard_task_runner.py:87} INFO - Running: ['***', 'tasks', 'run', 'gcs_snowflake_etl', 'transform_data', 'scheduled__2024-02-27T00:00:00+00:00', '--job-id', '75', '--raw', '--subdir', 'DAGS_FOLDER/GCS_to_Snowflake_DAG.py', '--cfg-path', '/tmp/tmp5tueu6f4']
[2024-02-28T13:07:35.175+0000] {standard_task_runner.py:88} INFO - Job 75: Subtask transform_data
[2024-02-28T13:07:35.262+0000] {task_command.py:423} INFO - Running <TaskInstance: gcs_snowflake_etl.transform_data scheduled__2024-02-27T00:00:00+00:00 [running]> on host b9a0bf70b495
[2024-02-28T13:07:35.417+0000] {taskinstance.py:2480} INFO - Exporting env vars: AIRFLOW_CTX_DAG_OWNER='stellar' AIRFLOW_CTX_DAG_ID='gcs_snowflake_etl' AIRFLOW_CTX_TASK_ID='transform_data' AIRFLOW_CTX_EXECUTION_DATE='2024-02-27T00:00:00+00:00' AIRFLOW_CTX_TRY_NUMBER='3' AIRFLOW_CTX_DAG_RUN_ID='scheduled__2024-02-27T00:00:00+00:00'
[2024-02-28T13:07:35.420+0000] {taskinstance.py:2698} ERROR - Task failed with exception
Traceback (most recent call last):
  File "/home/airflow/.local/lib/python3.8/site-packages/airflow/models/taskinstance.py", line 433, in _execute_task
    result = execute_callable(context=context, **execute_callable_kwargs)
  File "/home/airflow/.local/lib/python3.8/site-packages/airflow/operators/python.py", line 199, in execute
    return_value = self.execute_callable()
  File "/home/airflow/.local/lib/python3.8/site-packages/airflow/operators/python.py", line 216, in execute_callable
    return self.python_callable(*self.op_args, **self.op_kwargs)
  File "/opt/airflow/dags/GCS_to_Snowflake_DAG.py", line 31, in transform_data
    GOOGLE_APPLICATION_CREDENTIALS = os.environ["GOOGLE_APPLICATION_CREDENTIALS"]
  File "/usr/local/lib/python3.8/os.py", line 675, in __getitem__
    raise KeyError(key) from None
KeyError: 'GOOGLE_APPLICATION_CREDENTIALS'
[2024-02-28T13:07:35.437+0000] {taskinstance.py:1138} INFO - Marking task as UP_FOR_RETRY. dag_id=gcs_snowflake_etl, task_id=transform_data, execution_date=20240227T000000, start_date=20240228T130735, end_date=20240228T130735
[2024-02-28T13:07:35.457+0000] {standard_task_runner.py:107} ERROR - Failed to execute job 75 for task transform_data ('GOOGLE_APPLICATION_CREDENTIALS'; 75)
[2024-02-28T13:07:35.504+0000] {local_task_job_runner.py:234} INFO - Task exited with return code 1
[2024-02-28T13:07:35.543+0000] {taskinstance.py:3280} INFO - 0 downstream tasks scheduled from follow-on schedule check
[2024-02-28T13:13:54.547+0000] {taskinstance.py:1956} INFO - Dependencies all met for dep_context=non-requeueable deps ti=<TaskInstance: gcs_snowflake_etl.transform_data scheduled__2024-02-27T00:00:00+00:00 [queued]>
[2024-02-28T13:13:54.564+0000] {taskinstance.py:1956} INFO - Dependencies all met for dep_context=requeueable deps ti=<TaskInstance: gcs_snowflake_etl.transform_data scheduled__2024-02-27T00:00:00+00:00 [queued]>
[2024-02-28T13:13:54.565+0000] {taskinstance.py:2170} INFO - Starting attempt 3 of 5
[2024-02-28T13:13:54.607+0000] {taskinstance.py:2191} INFO - Executing <Task(PythonOperator): transform_data> on 2024-02-27 00:00:00+00:00
[2024-02-28T13:13:54.614+0000] {standard_task_runner.py:60} INFO - Started process 75 to run task
[2024-02-28T13:13:54.622+0000] {standard_task_runner.py:87} INFO - Running: ['***', 'tasks', 'run', 'gcs_snowflake_etl', 'transform_data', 'scheduled__2024-02-27T00:00:00+00:00', '--job-id', '86', '--raw', '--subdir', 'DAGS_FOLDER/GCS_to_Snowflake_DAG.py', '--cfg-path', '/tmp/tmpoksa4nuf']
[2024-02-28T13:13:54.628+0000] {standard_task_runner.py:88} INFO - Job 86: Subtask transform_data
[2024-02-28T13:13:54.722+0000] {task_command.py:423} INFO - Running <TaskInstance: gcs_snowflake_etl.transform_data scheduled__2024-02-27T00:00:00+00:00 [running]> on host b9a0bf70b495
[2024-02-28T13:13:54.868+0000] {taskinstance.py:2480} INFO - Exporting env vars: AIRFLOW_CTX_DAG_OWNER='stellar' AIRFLOW_CTX_DAG_ID='gcs_snowflake_etl' AIRFLOW_CTX_TASK_ID='transform_data' AIRFLOW_CTX_EXECUTION_DATE='2024-02-27T00:00:00+00:00' AIRFLOW_CTX_TRY_NUMBER='3' AIRFLOW_CTX_DAG_RUN_ID='scheduled__2024-02-27T00:00:00+00:00'
[2024-02-28T13:13:54.873+0000] {taskinstance.py:2698} ERROR - Task failed with exception
Traceback (most recent call last):
  File "/home/airflow/.local/lib/python3.8/site-packages/airflow/models/taskinstance.py", line 433, in _execute_task
    result = execute_callable(context=context, **execute_callable_kwargs)
  File "/home/airflow/.local/lib/python3.8/site-packages/airflow/operators/python.py", line 199, in execute
    return_value = self.execute_callable()
  File "/home/airflow/.local/lib/python3.8/site-packages/airflow/operators/python.py", line 216, in execute_callable
    return self.python_callable(*self.op_args, **self.op_kwargs)
  File "/opt/airflow/dags/GCS_to_Snowflake_DAG.py", line 32, in transform_data
    storage_client = storage.Client()
  File "/home/airflow/.local/lib/python3.8/site-packages/google/cloud/storage/client.py", line 172, in __init__
    super(Client, self).__init__(
  File "/home/airflow/.local/lib/python3.8/site-packages/google/cloud/client/__init__.py", line 320, in __init__
    _ClientProjectMixin.__init__(self, project=project, credentials=credentials)
  File "/home/airflow/.local/lib/python3.8/site-packages/google/cloud/client/__init__.py", line 268, in __init__
    project = self._determine_default(project)
  File "/home/airflow/.local/lib/python3.8/site-packages/google/cloud/client/__init__.py", line 287, in _determine_default
    return _determine_default_project(project)
  File "/home/airflow/.local/lib/python3.8/site-packages/google/cloud/_helpers/__init__.py", line 152, in _determine_default_project
    _, project = google.auth.default()
  File "/home/airflow/.local/lib/python3.8/site-packages/google/auth/_default.py", line 657, in default
    credentials, project_id = checker()
  File "/home/airflow/.local/lib/python3.8/site-packages/google/auth/_default.py", line 650, in <lambda>
    lambda: _get_explicit_environ_credentials(quota_project_id=quota_project_id),
  File "/home/airflow/.local/lib/python3.8/site-packages/google/auth/_default.py", line 270, in _get_explicit_environ_credentials
    credentials, project_id = load_credentials_from_file(
  File "/home/airflow/.local/lib/python3.8/site-packages/google/auth/_default.py", line 114, in load_credentials_from_file
    raise exceptions.DefaultCredentialsError(
google.auth.exceptions.DefaultCredentialsError: File D:\GCS_to_Snowflake_WithAirflow\credentials2de-workshop-369208-8179100cc99a.json was not found.
[2024-02-28T13:13:54.893+0000] {taskinstance.py:1138} INFO - Marking task as UP_FOR_RETRY. dag_id=gcs_snowflake_etl, task_id=transform_data, execution_date=20240227T000000, start_date=20240228T131354, end_date=20240228T131354
[2024-02-28T13:13:54.930+0000] {standard_task_runner.py:107} ERROR - Failed to execute job 86 for task transform_data (File D:\GCS_to_Snowflake_WithAirflow\credentials2de-workshop-369208-8179100cc99a.json was not found.; 75)
[2024-02-28T13:13:54.956+0000] {local_task_job_runner.py:234} INFO - Task exited with return code 1
[2024-02-28T13:13:55.001+0000] {taskinstance.py:3280} INFO - 0 downstream tasks scheduled from follow-on schedule check
[2024-02-28T13:19:18.912+0000] {taskinstance.py:1956} INFO - Dependencies all met for dep_context=non-requeueable deps ti=<TaskInstance: gcs_snowflake_etl.transform_data scheduled__2024-02-27T00:00:00+00:00 [queued]>
[2024-02-28T13:19:18.925+0000] {taskinstance.py:1956} INFO - Dependencies all met for dep_context=requeueable deps ti=<TaskInstance: gcs_snowflake_etl.transform_data scheduled__2024-02-27T00:00:00+00:00 [queued]>
[2024-02-28T13:19:18.926+0000] {taskinstance.py:2170} INFO - Starting attempt 3 of 5
[2024-02-28T13:19:18.962+0000] {taskinstance.py:2191} INFO - Executing <Task(PythonOperator): transform_data> on 2024-02-27 00:00:00+00:00
[2024-02-28T13:19:18.968+0000] {standard_task_runner.py:60} INFO - Started process 61 to run task
[2024-02-28T13:19:18.975+0000] {standard_task_runner.py:87} INFO - Running: ['***', 'tasks', 'run', 'gcs_snowflake_etl', 'transform_data', 'scheduled__2024-02-27T00:00:00+00:00', '--job-id', '105', '--raw', '--subdir', 'DAGS_FOLDER/GCS_to_Snowflake_DAG.py', '--cfg-path', '/tmp/tmpjmejr7tl']
[2024-02-28T13:19:18.980+0000] {standard_task_runner.py:88} INFO - Job 105: Subtask transform_data
[2024-02-28T13:19:19.070+0000] {task_command.py:423} INFO - Running <TaskInstance: gcs_snowflake_etl.transform_data scheduled__2024-02-27T00:00:00+00:00 [running]> on host b9a0bf70b495
[2024-02-28T13:19:19.220+0000] {taskinstance.py:2480} INFO - Exporting env vars: AIRFLOW_CTX_DAG_OWNER='stellar' AIRFLOW_CTX_DAG_ID='gcs_snowflake_etl' AIRFLOW_CTX_TASK_ID='transform_data' AIRFLOW_CTX_EXECUTION_DATE='2024-02-27T00:00:00+00:00' AIRFLOW_CTX_TRY_NUMBER='3' AIRFLOW_CTX_DAG_RUN_ID='scheduled__2024-02-27T00:00:00+00:00'
[2024-02-28T13:19:19.222+0000] {taskinstance.py:2698} ERROR - Task failed with exception
Traceback (most recent call last):
  File "/home/airflow/.local/lib/python3.8/site-packages/airflow/models/taskinstance.py", line 433, in _execute_task
    result = execute_callable(context=context, **execute_callable_kwargs)
  File "/home/airflow/.local/lib/python3.8/site-packages/airflow/operators/python.py", line 199, in execute
    return_value = self.execute_callable()
  File "/home/airflow/.local/lib/python3.8/site-packages/airflow/operators/python.py", line 216, in execute_callable
    return self.python_callable(*self.op_args, **self.op_kwargs)
  File "/opt/airflow/dags/GCS_to_Snowflake_DAG.py", line 32, in transform_data
    storage_client = storage.Client()
  File "/home/airflow/.local/lib/python3.8/site-packages/google/cloud/storage/client.py", line 172, in __init__
    super(Client, self).__init__(
  File "/home/airflow/.local/lib/python3.8/site-packages/google/cloud/client/__init__.py", line 320, in __init__
    _ClientProjectMixin.__init__(self, project=project, credentials=credentials)
  File "/home/airflow/.local/lib/python3.8/site-packages/google/cloud/client/__init__.py", line 268, in __init__
    project = self._determine_default(project)
  File "/home/airflow/.local/lib/python3.8/site-packages/google/cloud/client/__init__.py", line 287, in _determine_default
    return _determine_default_project(project)
  File "/home/airflow/.local/lib/python3.8/site-packages/google/cloud/_helpers/__init__.py", line 152, in _determine_default_project
    _, project = google.auth.default()
  File "/home/airflow/.local/lib/python3.8/site-packages/google/auth/_default.py", line 657, in default
    credentials, project_id = checker()
  File "/home/airflow/.local/lib/python3.8/site-packages/google/auth/_default.py", line 650, in <lambda>
    lambda: _get_explicit_environ_credentials(quota_project_id=quota_project_id),
  File "/home/airflow/.local/lib/python3.8/site-packages/google/auth/_default.py", line 270, in _get_explicit_environ_credentials
    credentials, project_id = load_credentials_from_file(
  File "/home/airflow/.local/lib/python3.8/site-packages/google/auth/_default.py", line 114, in load_credentials_from_file
    raise exceptions.DefaultCredentialsError(
google.auth.exceptions.DefaultCredentialsError: File ..\GCS_to_Snowflake_WithAirflow\credentials\r2de-workshop-369208-8179100cc99a.json was not found.
[2024-02-28T13:19:19.244+0000] {taskinstance.py:1138} INFO - Marking task as UP_FOR_RETRY. dag_id=gcs_snowflake_etl, task_id=transform_data, execution_date=20240227T000000, start_date=20240228T131918, end_date=20240228T131919
[2024-02-28T13:19:19.283+0000] {standard_task_runner.py:107} ERROR - Failed to execute job 105 for task transform_data (File ..\GCS_to_Snowflake_WithAirflow\credentials\r2de-workshop-369208-8179100cc99a.json was not found.; 61)
[2024-02-28T13:19:19.308+0000] {local_task_job_runner.py:234} INFO - Task exited with return code 1
[2024-02-28T13:19:19.387+0000] {taskinstance.py:3280} INFO - 0 downstream tasks scheduled from follow-on schedule check
[2024-02-28T14:18:08.767+0000] {taskinstance.py:1956} INFO - Dependencies all met for dep_context=non-requeueable deps ti=<TaskInstance: gcs_snowflake_etl.transform_data scheduled__2024-02-27T00:00:00+00:00 [queued]>
[2024-02-28T14:18:08.784+0000] {taskinstance.py:1956} INFO - Dependencies all met for dep_context=requeueable deps ti=<TaskInstance: gcs_snowflake_etl.transform_data scheduled__2024-02-27T00:00:00+00:00 [queued]>
[2024-02-28T14:18:08.785+0000] {taskinstance.py:2170} INFO - Starting attempt 3 of 3
[2024-02-28T14:18:08.825+0000] {taskinstance.py:2191} INFO - Executing <Task(PythonOperator): transform_data> on 2024-02-27 00:00:00+00:00
[2024-02-28T14:18:08.831+0000] {standard_task_runner.py:60} INFO - Started process 139 to run task
[2024-02-28T14:18:08.837+0000] {standard_task_runner.py:87} INFO - Running: ['***', 'tasks', 'run', 'gcs_snowflake_etl', 'transform_data', 'scheduled__2024-02-27T00:00:00+00:00', '--job-id', '213', '--raw', '--subdir', 'DAGS_FOLDER/GCS_to_Snowflake_DAG.py', '--cfg-path', '/tmp/tmpfp5g4k05']
[2024-02-28T14:18:08.842+0000] {standard_task_runner.py:88} INFO - Job 213: Subtask transform_data
[2024-02-28T14:18:08.959+0000] {task_command.py:423} INFO - Running <TaskInstance: gcs_snowflake_etl.transform_data scheduled__2024-02-27T00:00:00+00:00 [running]> on host 1753c686362f
[2024-02-28T14:18:09.130+0000] {taskinstance.py:2480} INFO - Exporting env vars: AIRFLOW_CTX_DAG_OWNER='stellar' AIRFLOW_CTX_DAG_ID='gcs_snowflake_etl' AIRFLOW_CTX_TASK_ID='transform_data' AIRFLOW_CTX_EXECUTION_DATE='2024-02-27T00:00:00+00:00' AIRFLOW_CTX_TRY_NUMBER='3' AIRFLOW_CTX_DAG_RUN_ID='scheduled__2024-02-27T00:00:00+00:00'
[2024-02-28T14:18:09.897+0000] {taskinstance.py:2698} ERROR - Task failed with exception
Traceback (most recent call last):
  File "/home/airflow/.local/lib/python3.8/site-packages/airflow/models/taskinstance.py", line 433, in _execute_task
    result = execute_callable(context=context, **execute_callable_kwargs)
  File "/home/airflow/.local/lib/python3.8/site-packages/airflow/operators/python.py", line 199, in execute
    return_value = self.execute_callable()
  File "/home/airflow/.local/lib/python3.8/site-packages/airflow/operators/python.py", line 216, in execute_callable
    return self.python_callable(*self.op_args, **self.op_kwargs)
  File "/opt/airflow/dags/GCS_to_Snowflake_DAG.py", line 41, in transform_data
    df.drop(columns=["Unnamed: 0"], inplace=True)
  File "/home/airflow/.local/lib/python3.8/site-packages/pandas/core/frame.py", line 5258, in drop
    return super().drop(
  File "/home/airflow/.local/lib/python3.8/site-packages/pandas/core/generic.py", line 4549, in drop
    obj = obj._drop_axis(labels, axis, level=level, errors=errors)
  File "/home/airflow/.local/lib/python3.8/site-packages/pandas/core/generic.py", line 4591, in _drop_axis
    new_axis = axis.drop(labels, errors=errors)
  File "/home/airflow/.local/lib/python3.8/site-packages/pandas/core/indexes/base.py", line 6699, in drop
    raise KeyError(f"{list(labels[mask])} not found in axis")
KeyError: "['Unnamed: 0'] not found in axis"
[2024-02-28T14:18:09.925+0000] {taskinstance.py:1138} INFO - Marking task as FAILED. dag_id=gcs_snowflake_etl, task_id=transform_data, execution_date=20240227T000000, start_date=20240228T141808, end_date=20240228T141809
[2024-02-28T14:18:09.955+0000] {standard_task_runner.py:107} ERROR - Failed to execute job 213 for task transform_data ("['Unnamed: 0'] not found in axis"; 139)
[2024-02-28T14:18:09.974+0000] {local_task_job_runner.py:234} INFO - Task exited with return code 1
[2024-02-28T14:18:10.027+0000] {taskinstance.py:3280} INFO - 0 downstream tasks scheduled from follow-on schedule check
