[2024-02-28T12:33:44.189+0000] {taskinstance.py:1956} INFO - Dependencies all met for dep_context=non-requeueable deps ti=<TaskInstance: gcs_snowflake_etl.transform_data scheduled__2024-02-27T00:00:00+00:00 [queued]>
[2024-02-28T12:33:44.201+0000] {taskinstance.py:1956} INFO - Dependencies all met for dep_context=requeueable deps ti=<TaskInstance: gcs_snowflake_etl.transform_data scheduled__2024-02-27T00:00:00+00:00 [queued]>
[2024-02-28T12:33:44.202+0000] {taskinstance.py:2170} INFO - Starting attempt 7 of 8
[2024-02-28T12:33:44.218+0000] {taskinstance.py:2191} INFO - Executing <Task(PythonOperator): transform_data> on 2024-02-27 00:00:00+00:00
[2024-02-28T12:33:44.224+0000] {standard_task_runner.py:60} INFO - Started process 53 to run task
[2024-02-28T12:33:44.229+0000] {standard_task_runner.py:87} INFO - Running: ['***', 'tasks', 'run', 'gcs_snowflake_etl', 'transform_data', 'scheduled__2024-02-27T00:00:00+00:00', '--job-id', '33', '--raw', '--subdir', 'DAGS_FOLDER/GCS_to_Snowflake_DAG.py', '--cfg-path', '/tmp/tmp8shh_p5a']
[2024-02-28T12:33:44.234+0000] {standard_task_runner.py:88} INFO - Job 33: Subtask transform_data
[2024-02-28T12:33:44.300+0000] {task_command.py:423} INFO - Running <TaskInstance: gcs_snowflake_etl.transform_data scheduled__2024-02-27T00:00:00+00:00 [running]> on host b9a0bf70b495
[2024-02-28T12:33:44.400+0000] {taskinstance.py:2480} INFO - Exporting env vars: AIRFLOW_CTX_DAG_OWNER='stellar' AIRFLOW_CTX_DAG_ID='gcs_snowflake_etl' AIRFLOW_CTX_TASK_ID='transform_data' AIRFLOW_CTX_EXECUTION_DATE='2024-02-27T00:00:00+00:00' AIRFLOW_CTX_TRY_NUMBER='7' AIRFLOW_CTX_DAG_RUN_ID='scheduled__2024-02-27T00:00:00+00:00'
[2024-02-28T12:33:44.403+0000] {taskinstance.py:2698} ERROR - Task failed with exception
Traceback (most recent call last):
  File "/home/airflow/.local/lib/python3.8/site-packages/airflow/models/taskinstance.py", line 433, in _execute_task
    result = execute_callable(context=context, **execute_callable_kwargs)
  File "/home/airflow/.local/lib/python3.8/site-packages/airflow/operators/python.py", line 199, in execute
    return_value = self.execute_callable()
  File "/home/airflow/.local/lib/python3.8/site-packages/airflow/operators/python.py", line 216, in execute_callable
    return self.python_callable(*self.op_args, **self.op_kwargs)
  File "/opt/airflow/dags/GCS_to_Snowflake_DAG.py", line 36, in transform_data
    storage_client = storage.Client()
  File "/home/airflow/.local/lib/python3.8/site-packages/google/cloud/storage/client.py", line 172, in __init__
    super(Client, self).__init__(
  File "/home/airflow/.local/lib/python3.8/site-packages/google/cloud/client/__init__.py", line 320, in __init__
    _ClientProjectMixin.__init__(self, project=project, credentials=credentials)
  File "/home/airflow/.local/lib/python3.8/site-packages/google/cloud/client/__init__.py", line 268, in __init__
    project = self._determine_default(project)
  File "/home/airflow/.local/lib/python3.8/site-packages/google/cloud/client/__init__.py", line 287, in _determine_default
    return _determine_default_project(project)
  File "/home/airflow/.local/lib/python3.8/site-packages/google/cloud/_helpers/__init__.py", line 152, in _determine_default_project
    _, project = google.auth.default()
  File "/home/airflow/.local/lib/python3.8/site-packages/google/auth/_default.py", line 657, in default
    credentials, project_id = checker()
  File "/home/airflow/.local/lib/python3.8/site-packages/google/auth/_default.py", line 650, in <lambda>
    lambda: _get_explicit_environ_credentials(quota_project_id=quota_project_id),
  File "/home/airflow/.local/lib/python3.8/site-packages/google/auth/_default.py", line 270, in _get_explicit_environ_credentials
    credentials, project_id = load_credentials_from_file(
  File "/home/airflow/.local/lib/python3.8/site-packages/google/auth/_default.py", line 114, in load_credentials_from_file
    raise exceptions.DefaultCredentialsError(
google.auth.exceptions.DefaultCredentialsError: File ./credentials/r2de-workshop-369208-8179100cc99a.json was not found.
[2024-02-28T12:33:44.418+0000] {taskinstance.py:1138} INFO - Marking task as UP_FOR_RETRY. dag_id=gcs_snowflake_etl, task_id=transform_data, execution_date=20240227T000000, start_date=20240228T123344, end_date=20240228T123344
[2024-02-28T12:33:44.433+0000] {standard_task_runner.py:107} ERROR - Failed to execute job 33 for task transform_data (File ./credentials/r2de-workshop-369208-8179100cc99a.json was not found.; 53)
[2024-02-28T12:33:44.483+0000] {local_task_job_runner.py:234} INFO - Task exited with return code 1
[2024-02-28T12:33:44.515+0000] {taskinstance.py:3280} INFO - 0 downstream tasks scheduled from follow-on schedule check
[2024-02-28T12:57:58.519+0000] {taskinstance.py:1956} INFO - Dependencies all met for dep_context=non-requeueable deps ti=<TaskInstance: gcs_snowflake_etl.transform_data scheduled__2024-02-27T00:00:00+00:00 [queued]>
[2024-02-28T12:57:58.537+0000] {taskinstance.py:1956} INFO - Dependencies all met for dep_context=requeueable deps ti=<TaskInstance: gcs_snowflake_etl.transform_data scheduled__2024-02-27T00:00:00+00:00 [queued]>
[2024-02-28T12:57:58.538+0000] {taskinstance.py:2170} INFO - Starting attempt 7 of 9
[2024-02-28T12:57:58.571+0000] {taskinstance.py:2191} INFO - Executing <Task(PythonOperator): transform_data> on 2024-02-27 00:00:00+00:00
[2024-02-28T12:57:58.578+0000] {standard_task_runner.py:60} INFO - Started process 86 to run task
[2024-02-28T12:57:58.583+0000] {standard_task_runner.py:87} INFO - Running: ['***', 'tasks', 'run', 'gcs_snowflake_etl', 'transform_data', 'scheduled__2024-02-27T00:00:00+00:00', '--job-id', '60', '--raw', '--subdir', 'DAGS_FOLDER/GCS_to_Snowflake_DAG.py', '--cfg-path', '/tmp/tmpdjehmjuo']
[2024-02-28T12:57:58.588+0000] {standard_task_runner.py:88} INFO - Job 60: Subtask transform_data
[2024-02-28T12:57:58.682+0000] {task_command.py:423} INFO - Running <TaskInstance: gcs_snowflake_etl.transform_data scheduled__2024-02-27T00:00:00+00:00 [running]> on host b9a0bf70b495
[2024-02-28T12:57:58.799+0000] {taskinstance.py:2480} INFO - Exporting env vars: AIRFLOW_CTX_DAG_OWNER='stellar' AIRFLOW_CTX_DAG_ID='gcs_snowflake_etl' AIRFLOW_CTX_TASK_ID='transform_data' AIRFLOW_CTX_EXECUTION_DATE='2024-02-27T00:00:00+00:00' AIRFLOW_CTX_TRY_NUMBER='7' AIRFLOW_CTX_DAG_RUN_ID='scheduled__2024-02-27T00:00:00+00:00'
[2024-02-28T12:57:58.802+0000] {taskinstance.py:2698} ERROR - Task failed with exception
Traceback (most recent call last):
  File "/home/airflow/.local/lib/python3.8/site-packages/airflow/models/taskinstance.py", line 433, in _execute_task
    result = execute_callable(context=context, **execute_callable_kwargs)
  File "/home/airflow/.local/lib/python3.8/site-packages/airflow/operators/python.py", line 199, in execute
    return_value = self.execute_callable()
  File "/home/airflow/.local/lib/python3.8/site-packages/airflow/operators/python.py", line 216, in execute_callable
    return self.python_callable(*self.op_args, **self.op_kwargs)
  File "/opt/airflow/dags/GCS_to_Snowflake_DAG.py", line 36, in transform_data
    storage_client = storage.Client()
  File "/home/airflow/.local/lib/python3.8/site-packages/google/cloud/storage/client.py", line 172, in __init__
    super(Client, self).__init__(
  File "/home/airflow/.local/lib/python3.8/site-packages/google/cloud/client/__init__.py", line 320, in __init__
    _ClientProjectMixin.__init__(self, project=project, credentials=credentials)
  File "/home/airflow/.local/lib/python3.8/site-packages/google/cloud/client/__init__.py", line 268, in __init__
    project = self._determine_default(project)
  File "/home/airflow/.local/lib/python3.8/site-packages/google/cloud/client/__init__.py", line 287, in _determine_default
    return _determine_default_project(project)
  File "/home/airflow/.local/lib/python3.8/site-packages/google/cloud/_helpers/__init__.py", line 152, in _determine_default_project
    _, project = google.auth.default()
  File "/home/airflow/.local/lib/python3.8/site-packages/google/auth/_default.py", line 657, in default
    credentials, project_id = checker()
  File "/home/airflow/.local/lib/python3.8/site-packages/google/auth/_default.py", line 650, in <lambda>
    lambda: _get_explicit_environ_credentials(quota_project_id=quota_project_id),
  File "/home/airflow/.local/lib/python3.8/site-packages/google/auth/_default.py", line 270, in _get_explicit_environ_credentials
    credentials, project_id = load_credentials_from_file(
  File "/home/airflow/.local/lib/python3.8/site-packages/google/auth/_default.py", line 114, in load_credentials_from_file
    raise exceptions.DefaultCredentialsError(
google.auth.exceptions.DefaultCredentialsError: File D:\GCS_to_Snowflake_WithAirflow\r2de-workshop-369208-8179100cc99a.json was not found.
[2024-02-28T12:57:58.821+0000] {taskinstance.py:1138} INFO - Marking task as UP_FOR_RETRY. dag_id=gcs_snowflake_etl, task_id=transform_data, execution_date=20240227T000000, start_date=20240228T125758, end_date=20240228T125758
[2024-02-28T12:57:58.842+0000] {standard_task_runner.py:107} ERROR - Failed to execute job 60 for task transform_data (File D:\GCS_to_Snowflake_WithAirflow\r2de-workshop-369208-8179100cc99a.json was not found.; 86)
[2024-02-28T12:57:58.876+0000] {local_task_job_runner.py:234} INFO - Task exited with return code 1
[2024-02-28T12:57:58.909+0000] {taskinstance.py:3280} INFO - 0 downstream tasks scheduled from follow-on schedule check
[2024-02-28T13:25:19.139+0000] {taskinstance.py:1956} INFO - Dependencies all met for dep_context=non-requeueable deps ti=<TaskInstance: gcs_snowflake_etl.transform_data scheduled__2024-02-27T00:00:00+00:00 [queued]>
[2024-02-28T13:25:19.186+0000] {taskinstance.py:1956} INFO - Dependencies all met for dep_context=requeueable deps ti=<TaskInstance: gcs_snowflake_etl.transform_data scheduled__2024-02-27T00:00:00+00:00 [queued]>
[2024-02-28T13:25:19.187+0000] {taskinstance.py:2170} INFO - Starting attempt 7 of 7
[2024-02-28T13:25:19.224+0000] {taskinstance.py:2191} INFO - Executing <Task(PythonOperator): transform_data> on 2024-02-27 00:00:00+00:00
[2024-02-28T13:25:19.234+0000] {standard_task_runner.py:60} INFO - Started process 76 to run task
[2024-02-28T13:25:19.246+0000] {standard_task_runner.py:87} INFO - Running: ['***', 'tasks', 'run', 'gcs_snowflake_etl', 'transform_data', 'scheduled__2024-02-27T00:00:00+00:00', '--job-id', '121', '--raw', '--subdir', 'DAGS_FOLDER/GCS_to_Snowflake_DAG.py', '--cfg-path', '/tmp/tmpuizec8wk']
[2024-02-28T13:25:19.255+0000] {standard_task_runner.py:88} INFO - Job 121: Subtask transform_data
[2024-02-28T13:25:19.376+0000] {task_command.py:423} INFO - Running <TaskInstance: gcs_snowflake_etl.transform_data scheduled__2024-02-27T00:00:00+00:00 [running]> on host b9a0bf70b495
[2024-02-28T13:25:19.542+0000] {taskinstance.py:2480} INFO - Exporting env vars: AIRFLOW_CTX_DAG_OWNER='stellar' AIRFLOW_CTX_DAG_ID='gcs_snowflake_etl' AIRFLOW_CTX_TASK_ID='transform_data' AIRFLOW_CTX_EXECUTION_DATE='2024-02-27T00:00:00+00:00' AIRFLOW_CTX_TRY_NUMBER='7' AIRFLOW_CTX_DAG_RUN_ID='scheduled__2024-02-27T00:00:00+00:00'
[2024-02-28T13:25:19.546+0000] {taskinstance.py:2698} ERROR - Task failed with exception
Traceback (most recent call last):
  File "/home/airflow/.local/lib/python3.8/site-packages/airflow/models/taskinstance.py", line 433, in _execute_task
    result = execute_callable(context=context, **execute_callable_kwargs)
  File "/home/airflow/.local/lib/python3.8/site-packages/airflow/operators/python.py", line 199, in execute
    return_value = self.execute_callable()
  File "/home/airflow/.local/lib/python3.8/site-packages/airflow/operators/python.py", line 216, in execute_callable
    return self.python_callable(*self.op_args, **self.op_kwargs)
  File "/opt/airflow/dags/GCS_to_Snowflake_DAG.py", line 32, in transform_data
    storage_client = storage.Client()
  File "/home/airflow/.local/lib/python3.8/site-packages/google/cloud/storage/client.py", line 172, in __init__
    super(Client, self).__init__(
  File "/home/airflow/.local/lib/python3.8/site-packages/google/cloud/client/__init__.py", line 320, in __init__
    _ClientProjectMixin.__init__(self, project=project, credentials=credentials)
  File "/home/airflow/.local/lib/python3.8/site-packages/google/cloud/client/__init__.py", line 268, in __init__
    project = self._determine_default(project)
  File "/home/airflow/.local/lib/python3.8/site-packages/google/cloud/client/__init__.py", line 287, in _determine_default
    return _determine_default_project(project)
  File "/home/airflow/.local/lib/python3.8/site-packages/google/cloud/_helpers/__init__.py", line 152, in _determine_default_project
    _, project = google.auth.default()
  File "/home/airflow/.local/lib/python3.8/site-packages/google/auth/_default.py", line 657, in default
    credentials, project_id = checker()
  File "/home/airflow/.local/lib/python3.8/site-packages/google/auth/_default.py", line 650, in <lambda>
    lambda: _get_explicit_environ_credentials(quota_project_id=quota_project_id),
  File "/home/airflow/.local/lib/python3.8/site-packages/google/auth/_default.py", line 270, in _get_explicit_environ_credentials
    credentials, project_id = load_credentials_from_file(
  File "/home/airflow/.local/lib/python3.8/site-packages/google/auth/_default.py", line 114, in load_credentials_from_file
    raise exceptions.DefaultCredentialsError(
google.auth.exceptions.DefaultCredentialsError: File ./GCS_to_Snowflake_WithAirflow/credentials/r2de-workshop-369208-8179100cc99a.json was not found.
[2024-02-28T13:25:19.562+0000] {taskinstance.py:1138} INFO - Marking task as FAILED. dag_id=gcs_snowflake_etl, task_id=transform_data, execution_date=20240227T000000, start_date=20240228T132519, end_date=20240228T132519
[2024-02-28T13:25:19.577+0000] {standard_task_runner.py:107} ERROR - Failed to execute job 121 for task transform_data (File ./GCS_to_Snowflake_WithAirflow/credentials/r2de-workshop-369208-8179100cc99a.json was not found.; 76)
[2024-02-28T13:25:19.619+0000] {local_task_job_runner.py:234} INFO - Task exited with return code 1
[2024-02-28T13:25:19.655+0000] {taskinstance.py:3280} INFO - 0 downstream tasks scheduled from follow-on schedule check
