[2024-02-29T18:05:13.925+0000] {taskinstance.py:1956} INFO - Dependencies all met for dep_context=non-requeueable deps ti=<TaskInstance: gcs_snowflake_etl.create_snowflake_database manual__2024-02-29T18:04:56.909758+00:00 [queued]>
[2024-02-29T18:05:13.938+0000] {taskinstance.py:1956} INFO - Dependencies all met for dep_context=requeueable deps ti=<TaskInstance: gcs_snowflake_etl.create_snowflake_database manual__2024-02-29T18:04:56.909758+00:00 [queued]>
[2024-02-29T18:05:13.939+0000] {taskinstance.py:2170} INFO - Starting attempt 1 of 3
[2024-02-29T18:05:13.958+0000] {taskinstance.py:2191} INFO - Executing <Task(SnowflakeOperator): create_snowflake_database> on 2024-02-29 18:04:56.909758+00:00
[2024-02-29T18:05:13.965+0000] {standard_task_runner.py:60} INFO - Started process 243 to run task
[2024-02-29T18:05:13.969+0000] {standard_task_runner.py:87} INFO - Running: ['***', 'tasks', 'run', 'gcs_snowflake_etl', 'create_snowflake_database', 'manual__2024-02-29T18:04:56.909758+00:00', '--job-id', '321', '--raw', '--subdir', 'DAGS_FOLDER/GCS_to_Snowflake_DAG.py', '--cfg-path', '/tmp/tmp7yeb9v5_']
[2024-02-29T18:05:13.975+0000] {standard_task_runner.py:88} INFO - Job 321: Subtask create_snowflake_database
[2024-02-29T18:05:14.043+0000] {task_command.py:423} INFO - Running <TaskInstance: gcs_snowflake_etl.create_snowflake_database manual__2024-02-29T18:04:56.909758+00:00 [running]> on host 1753c686362f
[2024-02-29T18:05:14.205+0000] {taskinstance.py:2480} INFO - Exporting env vars: AIRFLOW_CTX_DAG_OWNER='stellar' AIRFLOW_CTX_DAG_ID='gcs_snowflake_etl' AIRFLOW_CTX_TASK_ID='create_snowflake_database' AIRFLOW_CTX_EXECUTION_DATE='2024-02-29T18:04:56.909758+00:00' AIRFLOW_CTX_TRY_NUMBER='1' AIRFLOW_CTX_DAG_RUN_ID='manual__2024-02-29T18:04:56.909758+00:00'
[2024-02-29T18:05:14.208+0000] {sql.py:276} INFO - Executing: 
                    CREATE DATABASE IF NOT EXISTS Project_US_Stock_Market ;
            
[2024-02-29T18:05:14.228+0000] {base.py:83} INFO - Using connection ID 'conn_id_snowflake' for task execution.
[2024-02-29T18:05:14.244+0000] {base.py:83} INFO - Using connection ID 'conn_id_snowflake' for task execution.
[2024-02-29T18:05:14.245+0000] {connection.py:370} INFO - Snowflake Connector for Python Version: 3.6.0, Python Version: 3.8.18, Platform: Linux-5.15.133.1-microsoft-standard-WSL2-x86_64-with-glibc2.34
[2024-02-29T18:05:14.246+0000] {connection.py:1171} INFO - This connection is in OCSP Fail Open Mode. TLS Certificates would be checked for validity and revocation status. Any other Certificate Revocation related exceptions or OCSP Responder failures would be disregarded in favor of connectivity.
[2024-02-29T18:05:15.098+0000] {connection.py:547} WARNING - Certificate did not match expected hostname: qj22866.europe-west2.snowflakecomputing.com. Certificate: {'subject': ((('commonName', '*.prod3.us-west-2.snowflakecomputing.com'),),), 'subjectAltName': [('DNS', '*.prod3.us-west-2.snowflakecomputing.com'), ('DNS', '*.us-west-2.snowflakecomputing.com'), ('DNS', '*.global.snowflakecomputing.com'), ('DNS', '*.snowflakecomputing.com'), ('DNS', '*.prod3.us-west-2.aws.snowflakecomputing.com')]}
[2024-02-29T18:05:15.100+0000] {connectionpool.py:824} WARNING - Retrying (Retry(total=0, connect=None, read=None, redirect=None, status=None)) after connection broken by 'SSLError(CertificateError("hostname 'qj22866.europe-west2.snowflakecomputing.com' doesn't match either of '*.prod3.us-west-2.snowflakecomputing.com', '*.us-west-2.snowflakecomputing.com', '*.global.snowflakecomputing.com', '*.snowflakecomputing.com', '*.prod3.us-west-2.aws.snowflakecomputing.com'"))': /session/v1/login-request?request_id=1b4199ec-2af8-4441-a9e7-0eafdc52d22a&databaseName=Project_US_Stock_Market&schemaName=Stock_Market&warehouse=COMPUTE_WH&roleName=ACCOUNTADMIN&request_guid=befad187-8089-4c3c-97fc-3229c186c52f
[2024-02-29T18:05:15.841+0000] {connection.py:547} WARNING - Certificate did not match expected hostname: qj22866.europe-west2.snowflakecomputing.com. Certificate: {'subject': ((('commonName', '*.prod3.us-west-2.snowflakecomputing.com'),),), 'subjectAltName': [('DNS', '*.prod3.us-west-2.snowflakecomputing.com'), ('DNS', '*.us-west-2.snowflakecomputing.com'), ('DNS', '*.global.snowflakecomputing.com'), ('DNS', '*.snowflakecomputing.com'), ('DNS', '*.prod3.us-west-2.aws.snowflakecomputing.com')]}
[2024-02-29T18:05:15.847+0000] {network.py:1024} ERROR - Failed to get the response. Hanging? method: post, url: https://qj22866.europe-west2.snowflakecomputing.com:443/session/v1/login-request?request_id=1b4199ec-2af8-4441-a9e7-0eafdc52d22a&databaseName=Project_US_Stock_Market&schemaName=Stock_Market&warehouse=COMPUTE_WH&roleName=ACCOUNTADMIN&request_guid=befad187-8089-4c3c-97fc-3229c186c52f, headers:{'Content-Type': 'application/json', 'accept': 'application/snowflake', 'User-Agent': 'PythonConnector/3.6.0 (Linux-5.15.133.1-microsoft-standard-WSL2-x86_64-with-glibc2.34) CPython/3.8.18', 'Content-Encoding': 'gzip'}, data: {"data": {"CLIENT_APP_ID": "PythonConnector", "CLIENT_APP_VERSION": "3.6.0", "SVN_REVISION": null, "ACCOUNT_NAME": "qj22866", "LOGIN_NAME": "Grittapop", "CLIENT_ENVIRONMENT": {"APPLICATION": "AIRFLOW", "OS": "Linux", "OS_VERSION": "Linux-5.15.133.1-microsoft-standard-WSL2-x86_64-with-glibc2.34", "PYTHON_VERSION": "3.8.18", "PYTHON_RUNTIME": "CPython", "PYTHON_COMPILER": "GCC 12.2.0", "OCSP_MODE": "FAIL_OPEN", "TRACING": 20, "LOGIN_TIMEOUT": null, "NETWORK_TIMEOUT": null, "SOCKET_TIMEOUT": null}, "PASSWORD": "**** "SESSION_PARAMETERS": {"CLIENT_PREFETCH_THREADS": 4}}}
[2024-02-29T18:05:17.623+0000] {connection.py:547} WARNING - Certificate did not match expected hostname: qj22866.europe-west2.snowflakecomputing.com. Certificate: {'subject': ((('commonName', '*.prod3.us-west-2.snowflakecomputing.com'),),), 'subjectAltName': [('DNS', '*.prod3.us-west-2.snowflakecomputing.com'), ('DNS', '*.us-west-2.snowflakecomputing.com'), ('DNS', '*.global.snowflakecomputing.com'), ('DNS', '*.snowflakecomputing.com'), ('DNS', '*.prod3.us-west-2.aws.snowflakecomputing.com')]}
[2024-02-29T18:05:17.626+0000] {connectionpool.py:824} WARNING - Retrying (Retry(total=0, connect=None, read=None, redirect=None, status=None)) after connection broken by 'SSLError(CertificateError("hostname 'qj22866.europe-west2.snowflakecomputing.com' doesn't match either of '*.prod3.us-west-2.snowflakecomputing.com', '*.us-west-2.snowflakecomputing.com', '*.global.snowflakecomputing.com', '*.snowflakecomputing.com', '*.prod3.us-west-2.aws.snowflakecomputing.com'"))': /session/v1/login-request?request_id=47c889a4-ea88-41a7-929b-6dd8f123f50f&databaseName=Project_US_Stock_Market&schemaName=Stock_Market&warehouse=COMPUTE_WH&roleName=ACCOUNTADMIN&request_guid=2a61a7a0-09a7-4b2b-aff1-0f4bb09ebb3c
[2024-02-29T18:05:18.380+0000] {connection.py:547} WARNING - Certificate did not match expected hostname: qj22866.europe-west2.snowflakecomputing.com. Certificate: {'subject': ((('commonName', '*.prod3.us-west-2.snowflakecomputing.com'),),), 'subjectAltName': [('DNS', '*.prod3.us-west-2.snowflakecomputing.com'), ('DNS', '*.us-west-2.snowflakecomputing.com'), ('DNS', '*.global.snowflakecomputing.com'), ('DNS', '*.snowflakecomputing.com'), ('DNS', '*.prod3.us-west-2.aws.snowflakecomputing.com')]}
[2024-02-29T18:05:18.392+0000] {network.py:1024} ERROR - Failed to get the response. Hanging? method: post, url: https://qj22866.europe-west2.snowflakecomputing.com:443/session/v1/login-request?request_id=47c889a4-ea88-41a7-929b-6dd8f123f50f&databaseName=Project_US_Stock_Market&schemaName=Stock_Market&warehouse=COMPUTE_WH&roleName=ACCOUNTADMIN&request_guid=2a61a7a0-09a7-4b2b-aff1-0f4bb09ebb3c, headers:{'Content-Type': 'application/json', 'accept': 'application/snowflake', 'User-Agent': 'PythonConnector/3.6.0 (Linux-5.15.133.1-microsoft-standard-WSL2-x86_64-with-glibc2.34) CPython/3.8.18', 'Content-Encoding': 'gzip'}, data: {"data": {"CLIENT_APP_ID": "PythonConnector", "CLIENT_APP_VERSION": "3.6.0", "SVN_REVISION": null, "ACCOUNT_NAME": "qj22866", "LOGIN_NAME": "Grittapop", "CLIENT_ENVIRONMENT": {"APPLICATION": "AIRFLOW", "OS": "Linux", "OS_VERSION": "Linux-5.15.133.1-microsoft-standard-WSL2-x86_64-with-glibc2.34", "PYTHON_VERSION": "3.8.18", "PYTHON_RUNTIME": "CPython", "PYTHON_COMPILER": "GCC 12.2.0", "OCSP_MODE": "FAIL_OPEN", "TRACING": 20, "LOGIN_TIMEOUT": null, "NETWORK_TIMEOUT": null, "SOCKET_TIMEOUT": null}, "PASSWORD": "**** "SESSION_PARAMETERS": {"CLIENT_PREFETCH_THREADS": 4}}}
[2024-02-29T18:05:18.423+0000] {taskinstance.py:2698} ERROR - Task failed with exception
Traceback (most recent call last):
  File "/home/airflow/.local/lib/python3.8/site-packages/snowflake/connector/connection.py", line 1305, in _authenticate
    auth.authenticate(
  File "/home/airflow/.local/lib/python3.8/site-packages/snowflake/connector/auth/_auth.py", line 250, in authenticate
    ret = self._rest._post_request(
  File "/home/airflow/.local/lib/python3.8/site-packages/snowflake/connector/network.py", line 729, in _post_request
    ret = self.fetch(
  File "/home/airflow/.local/lib/python3.8/site-packages/snowflake/connector/network.py", line 838, in fetch
    ret = self._request_exec_wrapper(
  File "/home/airflow/.local/lib/python3.8/site-packages/snowflake/connector/network.py", line 974, in _request_exec_wrapper
    raise e
  File "/home/airflow/.local/lib/python3.8/site-packages/snowflake/connector/network.py", line 890, in _request_exec_wrapper
    self._handle_unknown_error(method, full_url, headers, data, conn)
  File "/home/airflow/.local/lib/python3.8/site-packages/snowflake/connector/network.py", line 1029, in _handle_unknown_error
    Error.errorhandler_wrapper(
  File "/home/airflow/.local/lib/python3.8/site-packages/snowflake/connector/errors.py", line 290, in errorhandler_wrapper
    handed_over = Error.hand_to_other_handler(
  File "/home/airflow/.local/lib/python3.8/site-packages/snowflake/connector/errors.py", line 348, in hand_to_other_handler
    connection.errorhandler(connection, cursor, error_class, error_value)
  File "/home/airflow/.local/lib/python3.8/site-packages/snowflake/connector/errors.py", line 221, in default_errorhandler
    raise error_class(
snowflake.connector.errors.OperationalError: 250003: 250003: Failed to get the response. Hanging? method: post, url: https://qj22866.europe-west2.snowflakecomputing.com:443/session/v1/login-request?request_id=1b4199ec-2af8-4441-a9e7-0eafdc52d22a&databaseName=Project_US_Stock_Market&schemaName=Stock_Market&warehouse=COMPUTE_WH&roleName=ACCOUNTADMIN&request_guid=befad187-8089-4c3c-97fc-3229c186c52f

The above exception was the direct cause of the following exception:

Traceback (most recent call last):
  File "/home/airflow/.local/lib/python3.8/site-packages/airflow/models/taskinstance.py", line 433, in _execute_task
    result = execute_callable(context=context, **execute_callable_kwargs)
  File "/home/airflow/.local/lib/python3.8/site-packages/airflow/providers/common/sql/operators/sql.py", line 282, in execute
    output = hook.run(
  File "/home/airflow/.local/lib/python3.8/site-packages/airflow/providers/snowflake/hooks/snowflake.py", line 382, in run
    with closing(self.get_conn()) as conn:
  File "/home/airflow/.local/lib/python3.8/site-packages/airflow/providers/snowflake/hooks/snowflake.py", line 276, in get_conn
    conn = connector.connect(**conn_config)
  File "/home/airflow/.local/lib/python3.8/site-packages/snowflake/connector/__init__.py", line 54, in Connect
    return SnowflakeConnection(**kwargs)
  File "/home/airflow/.local/lib/python3.8/site-packages/snowflake/connector/connection.py", line 413, in __init__
    self.connect(**kwargs)
  File "/home/airflow/.local/lib/python3.8/site-packages/snowflake/connector/connection.py", line 703, in connect
    self.__open_connection()
  File "/home/airflow/.local/lib/python3.8/site-packages/snowflake/connector/connection.py", line 1006, in __open_connection
    self.authenticate_with_retry(self.auth_class)
  File "/home/airflow/.local/lib/python3.8/site-packages/snowflake/connector/connection.py", line 1277, in authenticate_with_retry
    self._authenticate(auth_instance)
  File "/home/airflow/.local/lib/python3.8/site-packages/snowflake/connector/connection.py", line 1349, in _authenticate
    raise auth_op from e
  File "/home/airflow/.local/lib/python3.8/site-packages/snowflake/connector/connection.py", line 1326, in _authenticate
    auth_instance.handle_timeout(
  File "/home/airflow/.local/lib/python3.8/site-packages/snowflake/connector/auth/by_plugin.py", line 212, in handle_timeout
    raise error
snowflake.connector.errors.OperationalError: 250001: 250001: Could not connect to Snowflake backend after 2 attempt(s).Aborting
[2024-02-29T18:05:18.449+0000] {taskinstance.py:1138} INFO - Marking task as UP_FOR_RETRY. dag_id=gcs_snowflake_etl, task_id=create_snowflake_database, execution_date=20240229T180456, start_date=20240229T180513, end_date=20240229T180518
[2024-02-29T18:05:18.474+0000] {standard_task_runner.py:107} ERROR - Failed to execute job 321 for task create_snowflake_database (250001: 250001: Could not connect to Snowflake backend after 2 attempt(s).Aborting; 243)
[2024-02-29T18:05:18.492+0000] {local_task_job_runner.py:234} INFO - Task exited with return code 1
[2024-02-29T18:05:18.529+0000] {taskinstance.py:3280} INFO - 0 downstream tasks scheduled from follow-on schedule check
