[2024-02-28T16:33:21.554+0000] {taskinstance.py:1956} INFO - Dependencies all met for dep_context=non-requeueable deps ti=<TaskInstance: gcs_snowflake_etl.transform_data manual__2024-02-28T16:24:43.491411+00:00 [queued]>
[2024-02-28T16:33:21.568+0000] {taskinstance.py:1956} INFO - Dependencies all met for dep_context=requeueable deps ti=<TaskInstance: gcs_snowflake_etl.transform_data manual__2024-02-28T16:24:43.491411+00:00 [queued]>
[2024-02-28T16:33:21.569+0000] {taskinstance.py:2170} INFO - Starting attempt 6 of 8
[2024-02-28T16:33:21.596+0000] {taskinstance.py:2191} INFO - Executing <Task(PythonOperator): transform_data> on 2024-02-28 16:24:43.491411+00:00
[2024-02-28T16:33:21.603+0000] {standard_task_runner.py:60} INFO - Started process 75 to run task
[2024-02-28T16:33:21.608+0000] {standard_task_runner.py:87} INFO - Running: ['***', 'tasks', 'run', 'gcs_snowflake_etl', 'transform_data', 'manual__2024-02-28T16:24:43.491411+00:00', '--job-id', '259', '--raw', '--subdir', 'DAGS_FOLDER/GCS_to_Snowflake_DAG.py', '--cfg-path', '/tmp/tmp4mttlavs']
[2024-02-28T16:33:21.614+0000] {standard_task_runner.py:88} INFO - Job 259: Subtask transform_data
[2024-02-28T16:33:21.771+0000] {task_command.py:423} INFO - Running <TaskInstance: gcs_snowflake_etl.transform_data manual__2024-02-28T16:24:43.491411+00:00 [running]> on host 1753c686362f
[2024-02-28T16:33:21.884+0000] {taskinstance.py:2480} INFO - Exporting env vars: AIRFLOW_CTX_DAG_OWNER='stellar' AIRFLOW_CTX_DAG_ID='gcs_snowflake_etl' AIRFLOW_CTX_TASK_ID='transform_data' AIRFLOW_CTX_EXECUTION_DATE='2024-02-28T16:24:43.491411+00:00' AIRFLOW_CTX_TRY_NUMBER='6' AIRFLOW_CTX_DAG_RUN_ID='manual__2024-02-28T16:24:43.491411+00:00'
[2024-02-28T16:33:22.908+0000] {taskinstance.py:2698} ERROR - Task failed with exception
Traceback (most recent call last):
  File "/home/airflow/.local/lib/python3.8/site-packages/airflow/models/taskinstance.py", line 433, in _execute_task
    result = execute_callable(context=context, **execute_callable_kwargs)
  File "/home/airflow/.local/lib/python3.8/site-packages/airflow/operators/python.py", line 199, in execute
    return_value = self.execute_callable()
  File "/home/airflow/.local/lib/python3.8/site-packages/airflow/operators/python.py", line 216, in execute_callable
    return self.python_callable(*self.op_args, **self.op_kwargs)
  File "/opt/airflow/dags/GCS_to_Snowflake_DAG.py", line 63, in transform_data
    df.to_csv(destination_transform_data_file_name, index=False)
  File "/home/airflow/.local/lib/python3.8/site-packages/pandas/core/generic.py", line 3772, in to_csv
    return DataFrameRenderer(formatter).to_csv(
  File "/home/airflow/.local/lib/python3.8/site-packages/pandas/io/formats/format.py", line 1186, in to_csv
    csv_formatter.save()
  File "/home/airflow/.local/lib/python3.8/site-packages/pandas/io/formats/csvs.py", line 240, in save
    with get_handle(
  File "/home/airflow/.local/lib/python3.8/site-packages/pandas/io/common.py", line 737, in get_handle
    check_parent_directory(str(handle))
  File "/home/airflow/.local/lib/python3.8/site-packages/pandas/io/common.py", line 600, in check_parent_directory
    raise OSError(rf"Cannot save file into a non-existent directory: '{parent}'")
OSError: Cannot save file into a non-existent directory: 'transform_data'
[2024-02-28T16:33:22.931+0000] {taskinstance.py:1138} INFO - Marking task as UP_FOR_RETRY. dag_id=gcs_snowflake_etl, task_id=transform_data, execution_date=20240228T162443, start_date=20240228T163321, end_date=20240228T163322
[2024-02-28T16:33:22.988+0000] {standard_task_runner.py:107} ERROR - Failed to execute job 259 for task transform_data (Cannot save file into a non-existent directory: 'transform_data'; 75)
[2024-02-28T16:33:23.029+0000] {local_task_job_runner.py:234} INFO - Task exited with return code 1
[2024-02-28T16:33:23.064+0000] {taskinstance.py:3280} INFO - 0 downstream tasks scheduled from follow-on schedule check
