[2024-02-28T13:45:38.277+0000] {taskinstance.py:1956} INFO - Dependencies all met for dep_context=non-requeueable deps ti=<TaskInstance: gcs_snowflake_etl.transform_data manual__2024-02-28T13:35:14.314340+00:00 [queued]>
[2024-02-28T13:45:38.304+0000] {taskinstance.py:1956} INFO - Dependencies all met for dep_context=requeueable deps ti=<TaskInstance: gcs_snowflake_etl.transform_data manual__2024-02-28T13:35:14.314340+00:00 [queued]>
[2024-02-28T13:45:38.305+0000] {taskinstance.py:2170} INFO - Starting attempt 2 of 3
[2024-02-28T13:45:38.340+0000] {taskinstance.py:2191} INFO - Executing <Task(PythonOperator): transform_data> on 2024-02-28 13:35:14.314340+00:00
[2024-02-28T13:45:38.349+0000] {standard_task_runner.py:60} INFO - Started process 80 to run task
[2024-02-28T13:45:38.357+0000] {standard_task_runner.py:87} INFO - Running: ['***', 'tasks', 'run', 'gcs_snowflake_etl', 'transform_data', 'manual__2024-02-28T13:35:14.314340+00:00', '--job-id', '144', '--raw', '--subdir', 'DAGS_FOLDER/GCS_to_Snowflake_DAG.py', '--cfg-path', '/tmp/tmpdi1kiq7_']
[2024-02-28T13:45:38.362+0000] {standard_task_runner.py:88} INFO - Job 144: Subtask transform_data
[2024-02-28T13:45:38.444+0000] {task_command.py:423} INFO - Running <TaskInstance: gcs_snowflake_etl.transform_data manual__2024-02-28T13:35:14.314340+00:00 [running]> on host b9a0bf70b495
[2024-02-28T13:45:38.652+0000] {taskinstance.py:2480} INFO - Exporting env vars: AIRFLOW_CTX_DAG_OWNER='stellar' AIRFLOW_CTX_DAG_ID='gcs_snowflake_etl' AIRFLOW_CTX_TASK_ID='transform_data' AIRFLOW_CTX_EXECUTION_DATE='2024-02-28T13:35:14.314340+00:00' AIRFLOW_CTX_TRY_NUMBER='2' AIRFLOW_CTX_DAG_RUN_ID='manual__2024-02-28T13:35:14.314340+00:00'
[2024-02-28T13:45:38.667+0000] {_default.py:338} WARNING - Authentication failed using Compute Engine authentication due to unavailable metadata server.
[2024-02-28T13:45:38.668+0000] {taskinstance.py:2698} ERROR - Task failed with exception
Traceback (most recent call last):
  File "/home/airflow/.local/lib/python3.8/site-packages/airflow/models/taskinstance.py", line 433, in _execute_task
    result = execute_callable(context=context, **execute_callable_kwargs)
  File "/home/airflow/.local/lib/python3.8/site-packages/airflow/operators/python.py", line 199, in execute
    return_value = self.execute_callable()
  File "/home/airflow/.local/lib/python3.8/site-packages/airflow/operators/python.py", line 216, in execute_callable
    return self.python_callable(*self.op_args, **self.op_kwargs)
  File "/opt/airflow/dags/GCS_to_Snowflake_DAG.py", line 30, in transform_data
    storage_client = storage.Client()
  File "/home/airflow/.local/lib/python3.8/site-packages/google/cloud/storage/client.py", line 172, in __init__
    super(Client, self).__init__(
  File "/home/airflow/.local/lib/python3.8/site-packages/google/cloud/client/__init__.py", line 320, in __init__
    _ClientProjectMixin.__init__(self, project=project, credentials=credentials)
  File "/home/airflow/.local/lib/python3.8/site-packages/google/cloud/client/__init__.py", line 268, in __init__
    project = self._determine_default(project)
  File "/home/airflow/.local/lib/python3.8/site-packages/google/cloud/client/__init__.py", line 287, in _determine_default
    return _determine_default_project(project)
  File "/home/airflow/.local/lib/python3.8/site-packages/google/cloud/_helpers/__init__.py", line 152, in _determine_default_project
    _, project = google.auth.default()
  File "/home/airflow/.local/lib/python3.8/site-packages/google/auth/_default.py", line 691, in default
    raise exceptions.DefaultCredentialsError(_CLOUD_SDK_MISSING_CREDENTIALS)
google.auth.exceptions.DefaultCredentialsError: Your default credentials were not found. To set up Application Default Credentials, see https://cloud.google.com/docs/authentication/external/set-up-adc for more information.
[2024-02-28T13:45:38.688+0000] {taskinstance.py:1138} INFO - Marking task as UP_FOR_RETRY. dag_id=gcs_snowflake_etl, task_id=transform_data, execution_date=20240228T133514, start_date=20240228T134538, end_date=20240228T134538
[2024-02-28T13:45:38.718+0000] {standard_task_runner.py:107} ERROR - Failed to execute job 144 for task transform_data (Your default credentials were not found. To set up Application Default Credentials, see https://cloud.google.com/docs/authentication/external/set-up-adc for more information.; 80)
[2024-02-28T13:45:38.771+0000] {local_task_job_runner.py:234} INFO - Task exited with return code 1
[2024-02-28T13:45:38.894+0000] {taskinstance.py:3280} INFO - 0 downstream tasks scheduled from follow-on schedule check
